Workbook
Name CIENCIAS_AGRÍCOLAS: 'ÁREAS OCDE'!$A$25:$A$29
Name CIENCIAS_MÉDICAS_Y_DE_LA_SALUD: 'ÁREAS OCDE'!$A$20:$A$24
Name CIENCIAS_NATURALES: 'ÁREAS OCDE'!$A$2:$A$8
Name CIENCIAS_SOCIALES: 'ÁREAS OCDE'!$A$30:$A$38
Name HUMANIDADES: 'ÁREAS OCDE'!$A$39:$A$43
Name INGENIERÍA_Y_TECNOLOGÍA: 'ÁREAS OCDE'!$A$9:$A$19
Name OCDE: 'ÁREAS OCDE'!$B$2:$B$7

Sheet Índice
E1: GÚIA DE ANTECEDENTES PARA LA ACREDITACIÓN DE CARRERAS DE PREGRADO
B4: ÍNDICE
B6: Instructivo general
C7: 0. Resúmen estadístico
B9: Identificación de la carrera
C10: 1. Identificación de la carrera
B12: Objetivos y líneas de investigación
C13: 2. Líneas de investigación
B15: Estadísticas estudiantes
C16: 3. Admisión por ciclo-semestre
C17: 4. Cohortes por ciclo-semestre
C18: 5. Egresados por ciclo-semestre
C19: 6. Titulados por ciclo-semestre
C20: 7.a. Asignaturas y actvidades lectivas
C21: 7.b. Asignaturas optativas
C22: 8. Actualización del Plan de estudios
B24: Condiciones de operación
C25: 9. Consejo
C26: 10. Académicos
C27: 11. Caracterización académicos
C28: 12. Jefes de práctica
C29: 13. Perfeccionamiento académico
C30: 14. Personal no académico
C31: 15. Becas y ayudas internas
C32: 16. Becas y ayudas externas
C33: 17. Bienestar universitaro
C34: 18. Recursos de aprendizaje
B36: Investigación y vinculación con el medio
C37: 19. Desarrollo académico
C38: 20. Proyectos de investigación
C39: 21. Desarrollo profesional
C40: 22. Articulos
C41: 23. Libros o capítulos de libro
C42: 24. Obras de creación
C43: 25. Patentes
C44: 26. Redes
C45: 27. Extensión
C46: 28. Prestación de servicios

Sheet Instructivo general 
A1: INSTRUCTIVO GENERAL PARA COMPLETAR LA GUÍA DE ANTECEDENTES
A3: La Guía de antecedentes IAC-CINDA es un documento de apoyo a la recolección, producción, gestión y análisis de información para los programas que desarrollan su autoevaluación en el marco de procesos conducentes a la acreditación con el Instituto.
A4: El desarrollo de un proceso de autoevaluación exige rigurosidad metodológica en la obtención y procesamiento de la información. Esto permite sustentar los análisis y juicios evaluativos desarrollados por cada programa de manera adecuada, otorgando validez y confiabilidad a las conclusiones expresadas acerca de su calidad y desempeño.
A5: Cada programa deberá completar esta Guía y acompañar con ella a su informe de autoevaluación, por lo tanto, deberá ser completada de la manera más detallada y rigurosa posible, incluyendo en ella la información y anexos requeridos en cada apartado.
A6: IAC-CINDA recomienda no borrar secciones ni alterar la estructura base de la Guía de antecedentes durante el proceso de incorporación de los datos solicitados en ella, a fin de evitar la alteración de las formulas asociadas a algunos de sus campos o a la perdida de perspectiva respecto a los objetivos de cada apartado.
A7: Si su programa no cuenta con información sobre alguna de los apartados de la Guía de antecedentes, se solicita no dejar el espacio en blanco, sino completar dicho campo señalando “no aplica” o “sin información”. Asimismo, es importante considerar que cada hoja de la Guía de antecedentes tiene una sección especial dedicada a la incorporación de observaciones, esta puede ser utilizada en caso de que sea necesario aclarar o explicar algún término propio de la gestión del programa que requiera una mirada especial o una nota para quienes accedan a este documento.
A8: La sección- 0. Resumen estadístico- está diseñada para completarse de manera automática recogiendo los datos incluidos en las demás secciones de la Guía de antecedentes. Se solicita no ingresar en ella datos de manera manual y no modificar su estructura para evitar la desconfiguración de sus fórmulas.

Sheet 0. Resumen Estadístico
B1: RESUMEN ESTADÍSTICO | E1: Programa: | F1: ='1. Identificación carrera'!B6 -> 0 | I1: Institución: | J1: ='1. Identificación carrera'!B7 -> 0
B3: Esta sección recopila información estadística del programa. Esta diseñada para completarse automáticamente extrayendo la información de las demás secciones de la Guía de antecedentes. No ingrese datos manualmente ni modifique la estructura o casillas de esta sección.
B5: ESTADÍSTICAS ESTUDIANTES
C9: Vacantes, matrícula primer año (ingresantes) y matrícula total
C10: Ciclo-semestre | D10: Total vacantes | E10: Matrícula de primer año | F10: Matrícula total
C11: ='3. Admisión ciclo-semestre'!A9 -> 2022-I | D11: ='3. Admisión ciclo-semestre'!F9 -> 0 | E11: ='3. Admisión ciclo-semestre'!G9 -> 0 | F11: =SUM('4. Cohortes ciclo-semestre'!L18:U18) -> 0
C12: ='3. Admisión ciclo-semestre'!A10 -> 2022-II | D12: ='3. Admisión ciclo-semestre'!F10 -> 0 | E12: ='3. Admisión ciclo-semestre'!G10 -> 0 | F12: =SUM('4. Cohortes ciclo-semestre'!M19:U19) -> 0
C13: ='3. Admisión ciclo-semestre'!A11 -> 2023-I | D13: ='3. Admisión ciclo-semestre'!F11 -> 0 | E13: ='3. Admisión ciclo-semestre'!G11 -> 0 | F13: =SUM('4. Cohortes ciclo-semestre'!N20:U20) -> 0
C14: ='3. Admisión ciclo-semestre'!A12 -> 2023-II | D14: ='3. Admisión ciclo-semestre'!F12 -> 0 | E14: ='3. Admisión ciclo-semestre'!G12 -> 0 | F14: =SUM('4. Cohortes ciclo-semestre'!O21:U21) -> 0
C15: ='3. Admisión ciclo-semestre'!A13 -> 2024-I | D15: ='3. Admisión ciclo-semestre'!F13 -> 0 | E15: ='3. Admisión ciclo-semestre'!G13 -> 0 | F15: =SUM('4. Cohortes ciclo-semestre'!P22:U22) -> 0
C16: ='3. Admisión ciclo-semestre'!A14 -> 2024-II | D16: ='3. Admisión ciclo-semestre'!F14 -> 0 | E16: ='3. Admisión ciclo-semestre'!G14 -> 0 | F16: =SUM('4. Cohortes ciclo-semestre'!Q23:U23) -> 0
C17: ='3. Admisión ciclo-semestre'!A15 -> 2025-I | D17: ='3. Admisión ciclo-semestre'!F15 -> 0 | E17: ='3. Admisión ciclo-semestre'!G15 -> 0 | F17: =SUM('4. Cohortes ciclo-semestre'!R24:U24) -> 0
C18: ='3. Admisión ciclo-semestre'!A16 -> 2025-II | D18: ='3. Admisión ciclo-semestre'!F16 -> 0 | E18: ='3. Admisión ciclo-semestre'!G16 -> 0 | F18: =SUM('4. Cohortes ciclo-semestre'!S25:U25) -> 0
C19: ='3. Admisión ciclo-semestre'!A17 -> 2026-I | D19: ='3. Admisión ciclo-semestre'!F17 -> 0 | E19: ='3. Admisión ciclo-semestre'!G17 -> 0 | F19: =SUM('4. Cohortes ciclo-semestre'!T26:U26) -> 0
C20: ='3. Admisión ciclo-semestre'!A18 -> 2026-II | D20: ='3. Admisión ciclo-semestre'!F18 -> 0 | E20: ='3. Admisión ciclo-semestre'!G18 -> 0 | F20: ='4. Cohortes ciclo-semestre'!U27 -> 0
C24: Distribución matrícula de 1er año por género
C25: Ciclo-semestre | D25: Matrícula hombres | E25: Matrícula mujeres
C26: ='3. Admisión ciclo-semestre'!A9 -> 2022-I | D26: ='3. Admisión ciclo-semestre'!H9 -> 0 | E26: ='3. Admisión ciclo-semestre'!I9 -> 0
C27: ='3. Admisión ciclo-semestre'!A10 -> 2022-II | D27: ='3. Admisión ciclo-semestre'!H10 -> 0 | E27: ='3. Admisión ciclo-semestre'!I10 -> 0
C28: ='3. Admisión ciclo-semestre'!A11 -> 2023-I | D28: ='3. Admisión ciclo-semestre'!H11 -> 0 | E28: ='3. Admisión ciclo-semestre'!I11 -> 0
C29: ='3. Admisión ciclo-semestre'!A12 -> 2023-II | D29: ='3. Admisión ciclo-semestre'!H12 -> 0 | E29: ='3. Admisión ciclo-semestre'!I12 -> 0
C30: ='3. Admisión ciclo-semestre'!A13 -> 2024-I | D30: ='3. Admisión ciclo-semestre'!H13 -> 0 | E30: ='3. Admisión ciclo-semestre'!I13 -> 0
C31: ='3. Admisión ciclo-semestre'!A14 -> 2024-II | D31: ='3. Admisión ciclo-semestre'!H14 -> 0 | E31: ='3. Admisión ciclo-semestre'!I14 -> 0
C32: ='3. Admisión ciclo-semestre'!A15 -> 2025-I | D32: ='3. Admisión ciclo-semestre'!H15 -> 0 | E32: ='3. Admisión ciclo-semestre'!I15 -> 0
C33: ='3. Admisión ciclo-semestre'!A16 -> 2025-II | D33: ='3. Admisión ciclo-semestre'!H16 -> 0 | E33: ='3. Admisión ciclo-semestre'!I16 -> 0
C34: ='3. Admisión ciclo-semestre'!A17 -> 2026-I | D34: ='3. Admisión ciclo-semestre'!H17 -> 0 | E34: ='3. Admisión ciclo-semestre'!I17 -> 0
C35: ='3. Admisión ciclo-semestre'!A18 -> 2026-II | D35: ='3. Admisión ciclo-semestre'!H18 -> 0 | E35: ='3. Admisión ciclo-semestre'!I18 -> 0
C40: Tasas de deserción
C41: Cohorte de ingreso | D41: Tasa de deserción al primer año | E41: Tasa de deserción al segundo año | F41: Tasa de deserción al tercer año
C42: ='4. Cohortes ciclo-semestre'!A8 -> 2017-I | D42: ='4. Cohortes ciclo-semestre'!Y8 -> #DIV/0! | E42: ='4. Cohortes ciclo-semestre'!Z8 -> #DIV/0! | F42: ='4. Cohortes ciclo-semestre'!AA8 -> #DIV/0!
C43: ='4. Cohortes ciclo-semestre'!A9 -> 2017-II | D43: ='4. Cohortes ciclo-semestre'!Y9 -> #DIV/0! | E43: ='4. Cohortes ciclo-semestre'!Z9 -> #DIV/0! | F43: ='4. Cohortes ciclo-semestre'!AA9 -> #DIV/0!
C44: ='4. Cohortes ciclo-semestre'!A10 -> 2018-I | D44: ='4. Cohortes ciclo-semestre'!Y10 -> #DIV/0! | E44: ='4. Cohortes ciclo-semestre'!Z10 -> #DIV/0! | F44: ='4. Cohortes ciclo-semestre'!AA10 -> #DIV/0!
C45: ='4. Cohortes ciclo-semestre'!A11 -> 2018-II | D45: ='4. Cohortes ciclo-semestre'!Y11 -> #DIV/0! | E45: ='4. Cohortes ciclo-semestre'!Z11 -> #DIV/0! | F45: ='4. Cohortes ciclo-semestre'!AA11 -> #DIV/0!
C46: ='4. Cohortes ciclo-semestre'!A12 -> 2019-I | D46: ='4. Cohortes ciclo-semestre'!Y12 -> #DIV/0! | E46: ='4. Cohortes ciclo-semestre'!Z12 -> #DIV/0! | F46: ='4. Cohortes ciclo-semestre'!AA12 -> #DIV/0!
C47: ='4. Cohortes ciclo-semestre'!A13 -> 2019-II | D47: ='4. Cohortes ciclo-semestre'!Y13 -> #DIV/0! | E47: ='4. Cohortes ciclo-semestre'!Z13 -> #DIV/0! | F47: ='4. Cohortes ciclo-semestre'!AA13 -> #DIV/0!
C48: ='4. Cohortes ciclo-semestre'!A14 -> 2020-I | D48: ='4. Cohortes ciclo-semestre'!Y14 -> #DIV/0! | E48: ='4. Cohortes ciclo-semestre'!Z14 -> #DIV/0! | F48: ='4. Cohortes ciclo-semestre'!AA14 -> #DIV/0!
C49: ='4. Cohortes ciclo-semestre'!A15 -> 2020-II | D49: ='4. Cohortes ciclo-semestre'!Y15 -> #DIV/0! | E49: ='4. Cohortes ciclo-semestre'!Z15 -> #DIV/0! | F49: ='4. Cohortes ciclo-semestre'!AA15 -> #DIV/0!
C50: ='4. Cohortes ciclo-semestre'!A16 -> 2021-I | D50: ='4. Cohortes ciclo-semestre'!Y16 -> #DIV/0! | E50: ='4. Cohortes ciclo-semestre'!Z16 -> #DIV/0! | F50: ='4. Cohortes ciclo-semestre'!AA16 -> #DIV/0!
C51: ='4. Cohortes ciclo-semestre'!A17 -> 2021-II | D51: ='4. Cohortes ciclo-semestre'!Y17 -> #DIV/0! | E51: ='4. Cohortes ciclo-semestre'!Z17 -> #DIV/0! | F51: ='4. Cohortes ciclo-semestre'!AA17 -> #DIV/0!
C52: ='4. Cohortes ciclo-semestre'!A18 -> 2022-I | D52: ='4. Cohortes ciclo-semestre'!Y18 -> #DIV/0! | E52: ='4. Cohortes ciclo-semestre'!Z18 -> #DIV/0! | F52: ='4. Cohortes ciclo-semestre'!AA18 -> #DIV/0!
...

Sheet 1. Identificación carrera
A1: IDENTIFICACIÓN DEL PROGRAMA
A3: Esta sección aporta datos generales sobre el programa, su jornada, modalidades y las sedes en que se dicta. Asimismo, recopila información acerca de las áreas del conocimiento OCDE en las que el programa se integra.
A5: DATOS DE IDENTIFICACIÓN DEL PROGRAMA
A6: Programa
A7: Institución
A8: Número total de estudiantes matriculados (año en curso)
A9: Sede(s) en que se dicta (separadas por punto y coma (;)
A10: Jornada(es) en que se dicta
A11: Modalidad(es) en que se dicta
A12: Duración en años del programa | B12: 5
A13: Total de créditos
A14: Total de horas cronológicas del programa
A15: Año de inicio del programa
A17: Áreas y sub Áreas OCDE en las que se inscribe la carrera (seleccione de listado desplegable)
A18: Area OCDE 1 | B18: Sub Área OCDE 1
A21: Area OCDE 2 | B21: Sub Área OCDE 2
A24: Area OCDE 2 | B24: Sub Área OCDE 2
A29: Ciclos para los cuales proporcionará información. Ciclo 10 debe ser el más reciente para el cual se entrega información, y los otros deben ser los inmediatamente anteriores.
A30: Ciclo 1 | B30: 2022-I
A31: Ciclo 2 | B31: 2022-II
A32: Ciclo 3 | B32: 2023-I
A33: Ciclo 4 | B33: 2023-II
A34: Ciclo 5 | B34: 2024-I
A35: Ciclo 6 | B35: 2024-II
A36: Ciclo 7 | B36: 2025-I
A37: Ciclo 8 | B37: 2025-II
A38: Ciclo 9 | B38: 2026-I
A39: Ciclo 10 (último ciclo de referencia) | B39: 2026-II

Sheet 2. Líneas de investigación 
A1: OBJETIVOS Y LINEAS DE INVESTIGACIÓN DEL PROGRAMA
A3: Esta sección recopila información sobre los objetivos y líneas de investigación del programa
A5: Perfil de ingreso del programa
A9: Perfil de egreso del programa
A13: # | B13: Objetivos del programa
A19: # | B19: Objetivos del programa
A25: # | B25: Líneas de investigación

Sheet 3. Admisión ciclo-semestre
A1: ESTADÍSTICAS DE ADMISIÓN DEL PROGRAMA (POR AÑO)
A3: Esta sección recopila información que permite caracterizar a los estudiantes matriculados en el primer año del programa en los últimos 5 años. Aquí también se solicitan datos acerca de las vacantes ofrecidas por el programa en este período.
A5: Semestre (Ciclo) | B5: Datos generales admisión | H5: Distribución matrícula de 1er año por género | J5: Origen matrícula 1er año | N5: Distribución por tramo etario matrícula 1er año | R5: Observaciones
B6: Vacantes ordinarias | D6: Vacantes especiales | F6: Total vacantes [A] + [B] | G6: Matrícula total 1er año [C] + [D]
B7: Por vacantes ordinarias se entenderán los cupos definidos por un programa como disponibles para recibir a nuevos estudiantes a través de mecanismos regulares o generales de ingreso | D7: Por vacantes especiales se entenderán los cupos definidos por un programa como disponibles para recibir a nuevos estudiantes a través de mecanismos de ingreso extraordinarios (Por ejemplo: cupos con ingreso diferenciado para deportistas destacados; para estudiantes formados en el extranjero; por equidad de género, para estudiantes de pueblos indígenas o en situación de discapacidad) | J7: Al completar esta parte de la tabla es necesario tener a la vista que puede haber estudiantes que cumplan, al mismo tiempo, con más de una característica. Por tanto, es necesario trabajar cada columna de manera independiente | N7: Menor o igual a 18 años | O7: Mayor de 18 años y menor o igual a 21 años | P7: Mayor de 21 años y menor o igual a 25 años | Q7: Mayor de 25 años
B8: N° de vacantes ordinarias [A] | C8: N° estudiantes matriculados en primer año [C] | D8: N° de vacantes procesos especiales [B] | E8: N° estudiantes matriculados vía proceso especial [D] | H8: Matrícula total hombres | I8: Matrícula total mujeres | J8: N° de estudiantes de primer año provenientes de una ciudad del país distinta de aquella donde se dicta la carrera | K8: N° de estudiantes extranjeros ingresados en primer año | L8: N° de estudiantes de primer año que provienen de la educación pública | M8: N° de estudiantes de primer año que provienen de la educación privada
A9: ='1. Identificación carrera'!B30 -> 2022-I | F9: 0 | G9: 0
A10: ='1. Identificación carrera'!B31 -> 2022-II | F10: 0 | G10: 0
A11: ='1. Identificación carrera'!B32 -> 2023-I | F11: 0 | G11: 0
A12: ='1. Identificación carrera'!B33 -> 2023-II | F12: 0 | G12: 0
A13: ='1. Identificación carrera'!B34 -> 2024-I | F13: 0 | G13: 0
A14: ='1. Identificación carrera'!B35 -> 2024-II | F14: =B14+D14 -> 0 | G14: =C14+E14 -> 0
A15: ='1. Identificación carrera'!B36 -> 2025-I | F15: =B15+D15 -> 0 | G15: =C15+E15 -> 0
A16: ='1. Identificación carrera'!B37 -> 2025-II | F16: =B16+D16 -> 0 | G16: =C16+E16 -> 0
A17: ='1. Identificación carrera'!B38 -> 2026-I | F17: =B17+D17 -> 0 | G17: =C17+E17 -> 0
A18: ='1. Identificación carrera'!B39 -> 2026-II | F18: =B18+D18 -> 0 | G18: =C18+E18 -> 0

Sheet 4. Cohortes ciclo-semestre
A1: SEGUIMIENTO DE COHORTES POR SEMESTRE O CICLO
A3: Esta sección recopila información sobre el seguimiento y progresión de los estudiantes del programa. Los datos de esta sección permitirán conocer la matrícula del programa en los últimos diez años y dibujarán un panorama acerca de la deserción estudiantil, ofreciendo una mirada general del fenómeno a partir de totales por causal y de las tasas de deserción de estudiantes durante sus tres primeros años de formación.
A5: Cohorte (año y ciclo) de ingreso a la carrera (i) | B5: Matrícula en ciclos sucesivos por cohorte de ingreso | V5: Total estudiantes desertados por cohorte de ingreso | Y5: Tasas de deserción* | AB5: Observaciones
V6: Se considerará deserción el caso de aquellos estudiantes que abandonen el programa. Debe incorporarse en esta definición a aquellos estudiantes que habiendo congelado o suspendido sus estudios no se reintegren activamente al programa en los dos semestres o ciclos posteriores a dicha suspensión
B7: =A8 -> 2017-I | C7: =A9 -> 2017-II | D7: =A10 -> 2018-I | E7: =A11 -> 2018-II | F7: =$A12 -> 2019-I | G7: =$A13 -> 2019-II | H7: =$A14 -> 2020-I | I7: =$A15 -> 2020-II | J7: =$A16 -> 2021-I | K7: =$A17 -> 2021-II | L7: =$A18 -> 2022-I | M7: =$A19 -> 2022-II | N7: =$A20 -> 2023-I | O7: =$A21 -> 2023-II | P7: =$A22 -> 2024-I | Q7: =$A23 -> 2024-II | R7: =$A24 -> 2025-I | S7: =$A25 -> 2025-II | T7: =A26 -> 2026-I | U7: ='1. Identificación carrera'!B39 -> 2026-II | V7: Deserciones por motivos académicos | W7: Deserciones por motivos no académicos | X7: Deserción total | Y7: Tasa de deserción al primer año | Z7: Tasa de deserción al segundo año | AA7: Tasa de deserción al tercer año
A8: 2017-I | Y8: =(B8-D8)/B8 -> #DIV/0! | Z8: =(B8-F8)/B8 -> #DIV/0! | AA8: =(B8-H8)/B8 -> #DIV/0!
A9: 2017-II | Y9: =(C9-E9)/C9 -> #DIV/0! | Z9: =(C9-G9)/C9 -> #DIV/0! | AA9: =(C9-I9)/C9 -> #DIV/0!
A10: 2018-I | Y10: =(D10-F10)/D10 -> #DIV/0! | Z10: =(D10-H10)/D10 -> #DIV/0! | AA10: =(D10-J10)/D10 -> #DIV/0!
A11: 2018-II | Y11: =(E11-G11)/E11 -> #DIV/0! | Z11: =(E11-I11)/E11 -> #DIV/0! | AA11: =(E11-K11)/E11 -> #DIV/0!
A12: 2019-I | Y12: =(F12-H12)/F12 -> #DIV/0! | Z12: =(F12-J12)/F12 -> #DIV/0! | AA12: =(F12-L12)/F12 -> #DIV/0!
A13: 2019-II | Y13: =(G13-I13)/G13 -> #DIV/0! | Z13: =(G13-K13)/G13 -> #DIV/0! | AA13: =(G13-M13)/G13 -> #DIV/0!
A14: 2020-I | Y14: =(H14-J14)/H14 -> #DIV/0! | Z14: =(H14-L14)/H14 -> #DIV/0! | AA14: =(H14-N14)/H14 -> #DIV/0!
A15: 2020-II | Y15: =(I15-K15)/I15 -> #DIV/0! | Z15: =(I15-M15)/I15 -> #DIV/0! | AA15: =(I15-O15)/I15 -> #DIV/0!
A16: 2021-I | Y16: =(J16-L16)/J16 -> #DIV/0! | Z16: =(J16-N16)/J16 -> #DIV/0! | AA16: =(J16-P16)/J16 -> #DIV/0!
A17: 2021-II | Y17: =(K17-M17)/K17 -> #DIV/0! | Z17: =(K17-O17)/K17 -> #DIV/0! | AA17: =(K17-Q17)/K17 -> #DIV/0!
A18: 2022-I | Y18: =(L18-N18)/L18 -> #DIV/0! | Z18: =(L18-P18)/L18 -> #DIV/0! | AA18: =(K17-R17)/K17 -> #DIV/0!
A19: 2022-II | Y19: =(M19-O19)/M19 -> #DIV/0! | Z19: =(M19-Q19)/M19 -> #DIV/0! | AA19: =(M19-S19)/M19 -> #DIV/0!
A20: 2023-I | Y20: =(N20-P20)/N20 -> #DIV/0! | Z20: =(N20-R20)/N20 -> #DIV/0! | AA20: =(N20-T20)/N20 -> #DIV/0!
A21: 2023-II | Y21: =(O21-Q21)/O21 -> #DIV/0! | Z21: =(O21-S21)/O21 -> #DIV/0! | AA21: =(O21-U21)/O21 -> #DIV/0!
A22: 2024-I | Y22: =(P22-R22)/P22 -> #DIV/0! | Z22: =(P22-T22)/P22 -> #DIV/0!
A23: 2024-II | Y23: =(Q23-S23)/Q23 -> #DIV/0! | Z23: =(Q23-U23)/Q23 -> #DIV/0!
A24: 2025-I | Y24: =(R24-T24)/R24 -> #DIV/0!
A25: 2025-II | Y25: =(S25-U25)/S25 -> #DIV/0!
A26: 2026-I
A27: ='1. Identificación carrera'!B39 -> 2026-II
A31: * Fórmulas: Tasa de deserción al primer año: (N° estudiantes desertados por cohorte (i) al primer año (i+2 ciclos)/ N° estudiantes ingresados por cohorte (i) * 100. Tasa de deserción al segundo año: (N° estudiantes desertados por cohorte (i) al primer año (i+4 ciclos)/ N° estudiantes ingresados por cohorte (i) * 100. Tasa de deserción al tercer año: (N° estudiantes desertados por cohorte (i) al tercer año (i+6 ciclos)/ N° estudiantes ingresados por cohorte (i)) * 100.
A32: Notas: Cohorte de ingreso (i)

Sheet 5.Egresados ciclo-semestre
A1: EGRESADOS POR COHORTE POR SEMESTRE O CICLO
A3: Esta sección recoge información sobre el egreso de los estudiantes del programa, permitiendo conocer el número de años que los estudiantes del programa tardan en completar el conjunto de actividades lectivas integradas en su plan de estudios. Asimismo, entrega información acerca de la tasa de egreso por cohorte.
A5: Cohorte (año y ciclo) de ingreso a la carrera (i) | B5: Egresados en los últimos 10 ciclos | L5: Tasa de egreso por cohorte* | M5: Observaciones
B6: 2022-I | C6: 2022-II | D6: 2023-I | E6: 2023-II | F6: 2024-I | G6: 2024-II | H6: 2025-I | I6: 2025-II | J6: 2026-I | K6: 2026-II | L6: Porcentaje de estudiantes del programa que egresa por cohorte.
A7: 2017-I | L7: =SUM(B7:K7)/'[1]4.b.Cohortes semestre-ciclo'!B8 -> #DIV/0!
A8: 2017-II | L8: =SUM(B8:K8)/'[1]4.b.Cohortes semestre-ciclo'!C9 -> #DIV/0!
A9: 2018-I | L9: =SUM(B9:K9)/'[1]4.b.Cohortes semestre-ciclo'!D10 -> #DIV/0!
A10: 2018-II | L10: =SUM(B10:K10)/'[1]4.b.Cohortes semestre-ciclo'!E11 -> #DIV/0!
A11: 2019-I | L11: =SUM(B11:K11)/'[1]4.b.Cohortes semestre-ciclo'!F12 -> #DIV/0!
A12: 2019-II | L12: =SUM(B12:K12)/'[1]4.b.Cohortes semestre-ciclo'!G13 -> #DIV/0!
A13: 2020-I | L13: =SUM(B13:K13)/'[1]4.b.Cohortes semestre-ciclo'!H14 -> #DIV/0!
A14: 2020-II | L14: =SUM(B14:K14)/'[1]4.b.Cohortes semestre-ciclo'!I15 -> #DIV/0!
A15: 2021-I | L15: =SUM(B15:K15)/'[1]4.b.Cohortes semestre-ciclo'!J16 -> #DIV/0!
A16: 2021-II | L16: =SUM(B16:K16)/'[1]4.b.Cohortes semestre-ciclo'!K17 -> #DIV/0!
A19: * Fórmula: Tasa de egreso: ( ∑estudiantes egresados por cohorte (i) / N° estudiantes ingresados por cohorte (i)) * 100.
A20: Notas: Cohorte de ingreso (i)

Sheet 6. Titulados ciclo-semestre
A1: TITULADOS POR COHORTE POR SEMESTRE O CICLO
A3: Esta sección recoge información sobre la titulación de los estudiantes del programa y permite conocer el tiempo que los estudiantes del se tardan en completar el conjunto de actividades de graduación asociadas a su plan de estudios y obtener su título.
A4: Los datos recolectados en esta ección permiten conocer si existen brechas entre el tiempo proyectado para el cumplimiento de todas las actividades y requisitos asociados a la obtención del título y el tiempo, que en la realidad, tardan sus estudiantes para llevar adelante dichas actividades y culminarlas.
A6: Cohorte (año y ciclo) de ingreso a la carrera (i) | B6: Titulados en los últimos 10 ciclos | L6: Tasa de titulación* | N6: Observaciones
L7: Tasa de Titulación total | M7: Tasa de Titulación oportuna
B8: 2022-I | C8: 2022-II | D8: 2023-I | E8: 2023-II | F8: 2024-I | G8: 2024-II | H8: 2025-I | I8: 2025-II | J8: 2026-I | K8: 2026-II | L8: Porcentaje de estudiantes del programa que se titula por cohorte. | M8: Porcentaje de estudiantes que logra el cumplimiento de todas las actividades formativas, de egreso y de titulación asociadas a un programa de estudios dentro del tiempo proyectado para la duración de su desarrollo, más dos semestres o ciclos.
A9: 2017-I | L9: =SUM(B9:K9)/'[1]4.b.Cohortes semestre-ciclo'!B8 -> #DIV/0! | M9: =SUM(B9:D9)/'[1]4.b.Cohortes semestre-ciclo'!B8 -> #DIV/0!
A10: 2017-II | L10: =SUM(B10:K10)/'[1]4.b.Cohortes semestre-ciclo'!C9 -> #DIV/0! | M10: =SUM(C10:E10)/'[1]4.b.Cohortes semestre-ciclo'!C9 -> #DIV/0!
A11: 2018-I | L11: =SUM(B11:K11)/'[1]4.b.Cohortes semestre-ciclo'!D10 -> #DIV/0! | M11: =SUM(D11:F11)/'[1]4.b.Cohortes semestre-ciclo'!D10 -> #DIV/0!
A12: 2018-II | L12: =SUM(B12:K12)/'[1]4.b.Cohortes semestre-ciclo'!E11 -> #DIV/0! | M12: =SUM(E12:G12)/'[1]4.b.Cohortes semestre-ciclo'!E11 -> #DIV/0!
A13: 2019-I | L13: =SUM(B13:K13)/'[1]4.b.Cohortes semestre-ciclo'!F12 -> #DIV/0! | M13: =SUM(F13:H13)/'[1]4.b.Cohortes semestre-ciclo'!F12 -> #DIV/0!
A14: 2019-II | L14: =SUM(B14:K14)/'[1]4.b.Cohortes semestre-ciclo'!G13 -> #DIV/0! | M14: =SUM(G14:I14)/'[1]4.b.Cohortes semestre-ciclo'!G13 -> #DIV/0!
A15: 2020-I | L15: =SUM(B15:K15)/'[1]4.b.Cohortes semestre-ciclo'!H14 -> #DIV/0! | M15: =SUM(H15:J15)/'[1]4.b.Cohortes semestre-ciclo'!H14 -> #DIV/0!
A16: 2020-II | L16: =SUM(B16:K16)/'[1]4.b.Cohortes semestre-ciclo'!I15 -> #DIV/0! | M16: =SUM(I16:K16)/'[1]4.b.Cohortes semestre-ciclo'!I15 -> #DIV/0!
A17: 2021-I | L17: =SUM(B17:K17)/'[1]4.b.Cohortes semestre-ciclo'!J16 -> #DIV/0! | M17: =SUM(J17:K17)/'[1]4.b.Cohortes semestre-ciclo'!J16 -> #DIV/0!
A18: 2021-II | L18: =SUM(B18:K18)/'[1]4.b.Cohortes semestre-ciclo'!K17 -> #DIV/0! | M18: =SUM(K18)/'[1]4.b.Cohortes semestre-ciclo'!K17 -> #DIV/0!
A21: * Fórmulas: Tasa de Titulación total: ( ∑estudiantes titulados por cohorte (i) / N° estudiantes ingresados por cohorte (i)) * 100. Tasa de Titulación oportuna: (N° estudiantes titulados por cohorte en el tiempo teórico (i+10 ciclos) / N° estudiantes ingresados por cohorte (i)) * 100.
A22: Notas: Cohorte de ingreso (i)

Sheet 7.a. Asignaturas y actividades 
A1: ASIGNATURAS Y ACTIVIDADES CURRICULARES DEL PLAN DE ESTUDIOS VIGENTE MÁS ACTUAL
A3: Esta sección de la Guía de antecedentes recoge información sobre el plan de estudios del programa y los fundamentos generales que lo orientan.
A4: Cada programa deberá ingresar la información solicitada dando cuenta de cada curso o actividad curricular de su malla de estudios.
A6: # | B6: Semestre o ciclo de la malla en que se dicta | C6: Nombre de la asignatura o actividad curricular | D6: ¿Tiene pre-requisitos? (si/no) | E6: Número de veces en que se dicta cada año | F6: Número máximo de estudiantes por sección | G6: Línea Formativa en la que se integra | H6: Linea de investigación con la que se relaciona | I6: Créditos | J6: Observaciones
A7: 1
A8: 2
A9: 3
A10: 4
A11: 5
A12: 6
A13: 7
A14: 8
A15: 9
A16: 10
A17: 11
A18: 12
... A46: 40

Sheet 7.b. Asignaturas optativas
A1: ASIGNATURAS Y ACTIVIDADES ELECTIVAS OFRECIDAS EN EL PLAN DE ESTUDIOS MÁS ACTUAL DEL PROGRAMA
A3: Esta sección recoge información sobre las asignaturas o actividades electivas u optativas ofrecidas a los estudiantes del programa como parte de su malla curricular y los fundamentos que lo orientan.
A5: # | B5: Semestre o ciclo al que va dirigido | C5: Nombre de la asignatura o actividad curricular | D5: Número máximo de estudiantes por sección | E5: Línea Formativa en la que se integra | F5: Créditos | G5: Observaciones
A6: 1
A7: 2
A8: 3
A9: 4
A10: 5
A11: 6
A12: 7
A13: 8
A14: 9
A15: 10
A16: 11
A17: 12
... A45: 40

Sheet 8. Actualización Plan estudios
A1: ENTIDADES O PERSONAS QUE PARTICIPAN DE LA EVALUACIÓN Y ACTUALIZACIÓN DEL PLAN DE ESTUDIOS DEL PROGRAMA
A3: Esta sección recoge información acerca de las entidades encargadas de la actualización del plan de estudios.
A5: Entidades o personas que participan de la evaluación y actualización del plan de estudios del programa
A6: # | B6: Cargo/ entidad | C6: Periodicidad con que desarrolla su labor | D6: Observaciones
A7: 1
A8: 2
A9: 3
A10: 4
A11: 5
A12: 6
A13: 7
A14: 8
A15: 9
A16: 10
A17: 11
A18: 12
... A46: 40

Sheet 9. Consejo
A1: INTEGRANTES DEL CONSEJO DE LA UNIDAD RESPONSABLE DEL PROGRAMA O SU EQUIVALENTE
A3: Esta sección reune información acerca del Consejo de la unidad responsable del programa, incorporando datos acerca de su composición y de los mecanismos de elección de sus integranes.
A5: Integrantes del Consejo de la unidad responsable del programa o su equivalemte
A6: # | B6: Apellidos | C6: Nombres | D6: Cargo u ocupación principal | E6: Año de incorporación al consejo | F6: Mecanismo de selección o nombramiento | G6: Duración de su nombramiento (meses) | H6: Observaciones
A7: 1
A8: 2
A9: 3
A10: 4
A11: 5
A12: 6
A13: 7
A14: 8
A15: 9
A16: 10
A17: 11
A18: 12
... A56: 50

Sheet 10. Académicos
A1: CUERPO ACADÉMICO VINCULADO AL PROGRAMA (ÚLTIMO AÑO DE REFERENCIA)
A3: Esta sección busca recopilar información acerca del cuerpo académico vinculado al programa. Para ello se solicita incorporar en la tabla un conjunto de datos acerca de los docentes e investigadores relacionados con él tomando como referencia el último año del que dará cuenta su autoevaluación.
C5: Identificación e información general | E5: Grados académicos o títulos | Q5: Horas contratadas según tipo de actividad | V5: Cursos y asignaturas dictadas (últimos 5 años) | X5: Tesis o trabajos de titulación (últimos 5 años)
A6: # | B6: Año de referencia | C6: Apellidos | D6: Nombres | E6: Grado o título 1 | F6: Institución en que lo obtuvo | G6: Grado o título 2 | H6: Institución en que lo obtuvo | I6: Grado o título 3 | J6: Institución en que lo obtuvo | K6: Edad | L6: Año de incorporación a la institución | M6: Unidad a la que pertenece | N6: Jerarquía académica (rol o reconocimiento dentro del sistema de jerarquización o carrera docente de la institución ) | O6: Sistema nacional de investigación (Relación de cada académico con el Sistema nacional de investigación o sistema nacional de ciencia, innovación, desarrollo y tecnología ) | P6: Tipo de contrato | Q6: Gestión | R6: Docencia | S6: Investigación | T6: Otras | U6: Total de horas contratadas | V6: N° de cursos o asignaturas que ha impartido | W6: Nombre de los cursos o asignaturas (separados por punto y coma, poner entre parentesis años y semestres o ciclos en que se dictaron) | X6: N° de tesis o trabajos de titulación que ha dirigido | Y6: Título de las tesis o trabajos de titulación que ha dirigido (separados por punto y coma, poner entre parentesis años y semestres o ciclos en que se inscribieron) | Z6: Logros destacados, reconocimientos o premios obtenidos (indique el año entre paréntesis) | AA6: Observaciones
A7: 1 | U7: =SUM(Q7:T7) -> 0
A8: 2 | U8: =SUM(Q8:T8) -> 0
A9: 3 | U9: =SUM(Q9:T9) -> 0
A10: 4 | U10: =SUM(Q10:T10) -> 0
A11: 5 | U11: =SUM(Q11:T11) -> 0
A12: 6 | U12: =SUM(Q12:T12) -> 0
A13: 7 | U13: =SUM(Q13:T13) -> 0
A14: 8 | U14: =SUM(Q14:T14) -> 0
A15: 9 | U15: =SUM(Q15:T15) -> 0
A16: 10 | U16: =SUM(Q16:T16) -> 0
A17: 11 | U17: =SUM(Q17:T17) -> 0
A18: 12 | U18: =SUM(Q18:T18) -> 0
... A56: 50 | U56: =SUM(Q56:T56) -> 0

Sheet 11. Caracterización académicos 
A1: CARACTERIZACIÓN DE LOS ACADÉMICOS LIGADOS AL PROGRAMA (ÚLTIMO 5 AÑOS)
A3: Esta sección busca construir un panorama general acerca de la composición y mecanismos de contratación del cuerpo académico ligado al programa.
A5: NÚMERO DE ACADÉMICOS E INVESTIGADORES POR TIPO DE JORNADA | Y5: TOTAL ACADÉMICOS SEGÚN TRAMO ETARIO | AC5: NÚMERO DE ACADÉMICOS POR GRADO DE JERARQUÍA | AH5: Observaciones
A6: Ciclo-semestre | B6: Académicos jornada completa | I6: Académicos media jornada | P6: Académicos contratados por horas | W6: Total docentes [A]+[B]+[C]
B7: Número de docentes [A] | C7: Número de horas cronológicas destinadas a docencia directa (según reglamento) | E7: Grado académico | I7: Número de docentes [B] | J7: Número de horas cronológicas destinadas a docencia directa (según reglamento) | L7: Grado académico | P7: Número de docentes [C] | Q7: Número de horas cronológicas destinadas a docencia directa (según reglamento) | S7: Grado académico | AC7: Reemplace la categoría numerada de cada columna de esta sección con los nombres que representan los distintos escalafones de la jerarquía académica de la universidad
C8: Horas máximas | D8: Horas minimas | E8: Doctor | F8: Magister | G8: Licenciado | H8: Sin título ni grado | J8: Horas máximas | K8: Horas minimas | L8: Doctor | M8: Magister | N8: Licenciado | O8: Sin título ni grado | Q8: Horas máximas | R8: Horas minimas | S8: Doctor | T8: Magister | U8: Licenciado | V8: Sin título ni grado | Y8: Menores de 35 años | Z8: Entre 36 y 50 años | AA8: Entre 51 y 65 años | AB8: Mayores de 65 años | AC8: Categoría 1 | AD8: Categoría 2 | AE8: Categoría 3 | AF8: Categoría 4 | AG8: Categoría 5
A9: 2022-I | B9: =SUM(E9:H9) -> 0 | I9: =SUM(L9:O9) -> 0 | P9: =SUM(S9:V9) -> 0 | W9: =B9+I9+P9 -> 0
A10: 2022-II | B10: =SUM(E10:H10) -> 0 | I10: =SUM(L10:O10) -> 0 | P10: =SUM(S10:V10) -> 0 | W10: =B10+I10+P10 -> 0
A11: 2023-I | B11: =SUM(E11:H11) -> 0 | I11: =SUM(L11:O11) -> 0 | P11: =SUM(S11:V11) -> 0 | W11: =B11+I11+P11 -> 0
A12: 2023-II | B12: =SUM(E12:H12) -> 0 | I12: =SUM(L12:O12) -> 0 | P12: =SUM(S12:V12) -> 0 | W12: =B12+I12+P12 -> 0
A13: 2024-I | B13: =SUM(E13:H13) -> 0 | I13: =SUM(L13:O13) -> 0 | P13: =SUM(S13:V13) -> 0 | W13: =B13+I13+P13 -> 0
A14: 2024-II | B14: =SUM(E14:H14) -> 0 | I14: =SUM(L14:O14) -> 0 | P14: =SUM(S14:V14) -> 0 | W14: =B14+I14+P14 -> 0
A15: 2025-I | B15: =SUM(E15:H15) -> 0 | I15: =SUM(L15:O15) -> 0 | P15: =SUM(S15:V15) -> 0 | W15: =B15+I15+P15 -> 0
A16: 2025-II | B16: =SUM(E16:H16) -> 0 | I16: =SUM(L16:O16) -> 0 | P16: =SUM(S16:V16) -> 0 | W16: =B16+I16+P16 -> 0
A17: 2026-I | B17: =SUM(E17:H17) -> 0 | I17: =SUM(L17:O17) -> 0 | P17: =SUM(S17:V17) -> 0 | W17: =B17+I17+P17 -> 0
A18: 2026-II | B18: =SUM(E18:H18) -> 0 | I18: =SUM(L18:O18) -> 0 | P18: =SUM(S18:V18) -> 0 | W18: =B18+I18+P18 -> 0

Sheet 12. Jefes de práctica
A1: JEFES DE PRÁCTICA VINCULADOS AL PROGRAMA (DATOS DEL ÚLTIMO AÑO DE REFERENCIA)
A3: Esta sección recopila información acerca de los jefes de práctica del programa. En caso de que su programa no cuente con esta figura, por favor, déjela en blanco.
A5: Identificación e información general | I5: Contrato y carga | K5: Registro histórico de cursos o asignaturas en las que se ha desempeñado (últimos 5 años) | M5: Observaciones
A7: # | C7: Apellidos | D7: Nombres | E7: Grado académico o título | F7: Edad | G7: Año de incorporación o contratación en la institución | H7: Unidad a la que pertenece
B8: Año de referencia | I8: Tipo de contrato | J8: Horas contratadas | K8: N° de cursos o asignaturas en que participó | L8: Nombre de los cursos o asignaturas
A9: 1
A10: 2
A11: 3
A12: 4
A13: 5
A14: 6
A15: 7
A16: 8
A17: 9
A18: 10
A19: 11
A20: 12
... A58: 50

Sheet 13. Perfeccionamiento académic
A1: DOCENTES E INVESTIGADORES DEL PROGRAMA QUE HAN CURSADO O SEGUIDO INSTANCIAS DE PERFECCIONAMIENTO ACADÉMICO (ÚLTIMOS 5 AÑOS)
A3: Esta sección recopila información sobre las instancias de perfeccionamiento académico (capacitaciones, especializaciones o estudios de posgrado) que los docentes e investigadores del programa han llevado adelante en los últimos 5 años, es decir, está centrada en la puesta en valor de las acciones que el programa o su institución responsable han impulsado con el fin de consolidar un cuerpo académico de excelencia.
C5: Datos de identificación de docentes e investigadores participantes | E5: Identificación y características de las actividad de perfeccionamiento | I5: Tiempo total destinado a la actividad de perfeccionamiento (Indicar solo una opción para la duración de la actividad) | L5: Mecanismos de apoyo institucional
A6: # | B6: Año | C6: Apellidos | D6: Nombres | E6: Nombre | F6: Breve descripción | G6: Institución o entidad responsable de su dictado | H6: Relación con los requerimientos y orientaciones prioritarias del programa | I6: Horas | J6: Meses | K6: Semestres | L6: Total | M6: Parcial (Indique porcentaje) | N6: Liberación de carga lectiva u otras oblicaciones (Describa brevemente en qué consistió este apoyo) | O6: Otros | P6: Observaciones
A7: 1
A8: 2
A9: 3
A10: 4
A11: 5
A12: 6
A13: 7
A14: 8
A15: 9
A16: 10
A17: 11
A18: 12
... A55: 49

Sheet 14. Personal no académico
A1: PERSONAL DE GESTIÓN, ADMINISTRACIÓN Y TÉCNICO DEL PROGRAMA O DE SU UNIDAD RESPONSABLE (ÚLTIMO AÑO DE REFERENCIA)
A3: Esta sección recoge información acerca del equipo de gestión, administración y apoyo técnico que trabaja para el desarrollo de las actividades asociadas al desarrollo de la carrera.
A5: # | B5: Año de referencia | C5: Apellidos | D5: Nombres | E5: Cargo u ocupación principal | F5: Descripción general de sus funciones | G5: Año de incorporación al programa o a su unidad responsable | H5: Título o grado académico | I5: Tipo de contrato | J5: Dedicación horaria | K5: Observaciones
A6: 1
A7: 2
A8: 3
A9: 4
A10: 5
A11: 6
A12: 7
A13: 8
A14: 9
A15: 10
A16: 11
A17: 12
... A55: 50

Sheet 15. Becas y ayudas internas
A1: BECAS Y AYUDAS SOCIOECONÓMICAS PARA ESTUDIANTES OFRECIDAS POR EL PROGRAMA O LA INSTITUCIÓN (ÚLTIMO AÑO DE REFERENCIA)
A2: Esta sección recoge información sobre las becas y ayudas socioeconómicas para estudiantes ofrecidas por el programa o su institución resposable, con énfasis en los beneficiarios y las condiciones generales de obtención de los apoyos.
A5: # | B5: Año de referencia | C5: Identificación de la beca o ayuda | L5: Beneficiarios | N5: Observaciones
C6: Nombre de la beca o ayuda socioeconómica | D6: Descripción de la beca o ayuda | E6: Nivel al que se gestiona (marque con una cruz) | H6: Destinatarios | I6: Requisitos de potulación | J6: Duración del beneficio | K6: Condiciones de renovación y mantenimiento de la beca o ayuda | L6: Número total de estudiantes beneficiarios | M6: Porcentaje (%) de estudiantes beneficiarios
E7: Institucional | F7: Facultad | G7: Programa | H7: Estudiantes a los que va dirigida la beca o ayuda | M7: Respecto del total de estudiantes matriculados en el programa durante el período reportado
A9: 2
A10: 1
A11: 3
A12: 4
A13: 5
A14: 6
A15: 7
A16: 8
A17: 9
A18: 10

Sheet 16. Becas y ayudas externas
A1: BECAS Y AYUDAS SOCIOECONÓMICAS OFRECIDAS POR ORGANISMOS EXTERNOS A LA INSTITUCIÓN A LOS QUE ACCEDIERON LOS ESTUDIANTES DEL PROGRAMA (ÚLTIMO AÑO DE REFERENCIA)
A3: Esta sección recoge información sobre las becas y ayudas económicas que benefician a los estudiantes del programa y que son entregadas por organismos externos a su institución, atendiendo al carácter de las organizaciones que entregan dichos beneficios, las condiciones generales de obtención de los apoyos y el impacto de estos en el cuerpo estudiantil del programa.
A5: # | B5: Año de referencia | C5: Nombre de la beca o ayuda económica | D5: Institución u organo que lo entrega | E5: Descripción de la beca o ayuda | F5: Destinatarios o benficiaros (Estudiantes a los que va dirigida la beca o ayuda ) | G5: Requisitos de elegibilidad para las instituciones o programas de los potenciales beneficiarios | H5: Requisitos de postulación para estudiantes | I5: Duración del apoyo | J5: Condiciones de renovación y mantenimiento de la beca o ayuda | K5: Número total de estudiantes beneficiarios | L5: Porcentaje (%) de estudiantes beneficiarios (Respecto del total de estudiantes matriculados en el programa durante el período reportado) | M5: Observaciones
A6: 1
A7: 2
A8: 3
A9: 4
A10: 5
A11: 6
A12: 7
A13: 8
A14: 9
A15: 10
A16: 11
A17: 12
... A55: 50

Sheet 17. Bienestar universitario
A1: SERVICIOS O PROGRAMAS DE BIENESTAR UNIVERSITARIO INTEGRAL OFRECIDOS A LA COMUNIDAD ACADÉMICA DEL PROGRAMA POR ESTE O SU INSTITUCIÓN RESPONSABLE (DATOS DEL ÚLTIMO AÑO DE REFERENCIA)
A2: Esta sección recoge información acerca de los servicios de bienestar universitario ofrecidos por el programa o su institución responsable, atendiendo a su alcance, impacto y características generales.
A3: Para un manejo más cómodo de los datos, se han identificado los elementos relacionados con el programa con letras mayúsculas y en color azul y los referidos a la institución en su conjunto con letras mínusculas y amarillo.
A5: # | B5: Año de referencia | C5: Identificación general de los servicios o programas | F5: Beneficiarios directos | T5: Observaciones
C6: Nombre del servicio o programa | D6: Descripción | E6: Destinatarios | F6: Estudiantes del programa | H6: Estudiantes de la institución | J6: Docentes e investigadores | L6: Jefes de práctica | N6: Personal no académico | P6: Egresados | R6: Total de beneficiarios a nivel del programa (A+B+C+D+E+F) | S6: Total de beneficiarios a nivel institucional (a+b+c+d+e+f)
F8: Número (A) | G8: Porcentaje (%) (respecto del total de matriculados) | H8: Número (a) | I8: Porcentaje (%) (respecto del total de matriculados) | J8: Programa (B) | K8: Institución (b) | L8: Programa (C) | M8: Institución (c) | N8: Programa (D) | O8: Institución (d) | P8: Programa (E) | Q8: Institución (e)
A9: 1
A10: 2
A11: 3
A12: 4
A13: 5
A14: 6
A15: 7
A16: 8
A17: 9
A18: 10
A19: 11
A20: 12
... A58: 50

Sheet 18. Recursos de aprendizaje
A1: RECURSOS EDUCATIVOS UTILIZADOS PARA EL DESARROLLO DE LAS ACTIVIDADES LECTIVAS ASOCIADAS AL PLAN DE ESTUDIOS DEL PROGRAMA (DATOS DEL ÚLTIMO AÑO DE REFERENCIA)
A3: Esta sección recolecta información acerca de los recursos educativos (hemerotecas, colecciones digitales, repositorios académicos, colecciones audiovisuales, archivos documentales, recursos tecnológicos, entre otros) orientados al logro de los objetivos de formación asociados al perfil de egreso del programa y disponibles para su comunidad educativa en el último año de referencia.
C5: Identificación general de los recursos | H5: Usuarios del programa | L5: Requisitos y reglamentos para su utilización
H6: Números totales | L6: según tipo de usuario
A7: # | B7: Año de referencia | C7: Nombre del recurso | D7: Colección, repositorio, insumo tecnológico, etc | E7: Breve descripción | F7: Cantidad disponible | G7: Instancia encargada de su gestión | H7: N° Estudiantes | I7: N° docentes e investigadores | J7: N° Jefes de práctica | K7: N° Total de usuarios | L7: Estudiantes | M7: Tesistas | N7: Profesores tiempo completo | O7: Profesores tiempo parcial | P7: Jefes de práctica
A8: 1
A9: 2
A10: 3
A11: 4
A12: 5
A13: 6
A14: 7
A15: 8
A16: 9
A17: 10
A18: 11
A19: 12
... A57: 50

Sheet 19. Desarrollo académico
A1: ACTIVIDADES DE DESARROLLO ACADÉMICO (ÚLTIMOS 5 AÑOS)
A3: Esta sección recopila información acerca de las actividades de desarrollo académico llevadas adelante por docentes e investigadores(as) del programa, atendiendo a sus características generales, impacto, evaluación y recursos vinculados. Entenderemos como actividades de desarrollo académico la participación en congresos, seminarios, pasantías, intercambios y reuniones técnicas nacionales o internacionales.
A5: Descripción general de las actividades | M5: Participantes | O5: Impacto en el programa, evaluación y productos comprometidos | S5: Financiamiento, apoyos y recursos utilizados
S6: Expresar en moneda local
A7: # | B7: Caracterización de la actividad | G7: Año | H7: Período en que se realizó | J7: Línea de investigación o área de desarrollo del programa en la que se integra | K7: Responsable | M7: N° académicos Tiempo Completo participantes | N7: N° académicos a Tiempo Parcial participantes | O7: Impacto proyectado para el desarrollo del programa | P7: Actividades o productos desarrollados o comprometidos en el marco de la actividad | Q7: Mecanismos de difusión de la actividad y sus resultados entre actores clave del programa | R7: Mecanismos utilizados para evaluar la actividad | S7: Recursos no monetarios | T7: Apoyos no monetarios | U7: Financiamiento interno (del programa o la institución) | X7: Financiamiento externo (aportado por una institución ajena a la universidad) | AA7: Autofinanciado | AB7: Monto total del proyecto (en USD)
B8: Tipo | C8: Nombre | D8: Ciudad en que se realizó | E8: País | F8: Institución u organismo en que se llevó a cabo | H8: Formato fecha corta | S8: Utilización de espacios físicos, donaciones de material institucional, apoyos para promocionar el evento, colaboraciones, etc. | T8: Días de permiso, liberación de horas para equipo responsable, días libres compensatoríos, etc | AA8: Indique el porcentaje (%) del costo total de la actividad financiado con recursos pertenecientes al responsable de la actividad o su equipo de trabajo y no aportados ni por la institución ni por proyectos externos
B9: Congresos, seminarios, pasantías, intercambios, o reuniones técnicas | C9: Por ejemplo: 1er congreso de medicina veterinaria, o XV Jornadas de literatura fantástica | H9: Inicio | I9: Fin | K9: Nombre | L9: Rol desempeñado en la actividad | U9: Monto aportado (en USD) | V9: Porcentaje (%) del costo total de la actividad aportado | W9: Origen del financiamiento interno | X9: Monto aportado (en USD) | Y9: Porcentaje (%) del costo total de la actividad aportado | Z9: Origen del financiamiento externo
A10: 1 | AB10: =W10+Y10 -> 0
A11: 2 | AB11: =W11+Y11 -> 0
A12: 3 | AB12: =W12+Y12 -> 0
A13: 4 | AB13: =W13+Y13 -> 0
A14: 5 | AB14: =W14+Y14 -> 0
A15: 6 | AB15: =W15+Y15 -> 0
A16: 7 | AB16: =W16+Y16 -> 0
A17: 8 | AB17: =W17+Y17 -> 0
A18: 9 | AB18: =W18+Y18 -> 0
A19: 10 | AB19: =W19+Y19 -> 0
A20: 11 | AB20: =W20+Y20 -> 0
A21: 12 | AB21: =W21+Y21 -> 0
... A59: 50 | AB59: =W59+Y59 -> 0

Sheet 20. Proyectos de investigación
A1: PROYECTOS DE INVESTIGACIÓN DESARROLLADOS POR DOCENTES E INVESTIGADORES DEL PROGRAMA DURANTE LOS ÚLTIMOS 5 AÑOS
A2: PROYECTOS DE INVESTIGACIÓN LIDERADOS POR DOCENTES E INVESTIGADORES DEL PROGRAMA (ÚLTIMOS 5 AÑOS)
A4: Esta sección recopila información sobre los proyectos de investigación liderados o conducidos por docentes e investigadores del programa, atendiendo a sus características generales; equipo responsable; participantes; resultados; productos y financiamiento (entre otros elementos).
A5: Para completar esta sección se solicita que, en aquellas columnas en que haga falta integrar más de un elemento, cada uno de ellos vaya separado de los demás con un punto y coma (;).
B7: Información general del proyecto | J7: Co-Investigador(a)(s) responsable(s) | M7: Académicos de Tiempo Completo del programa | O7: Académicos de Tiempo Parcial del programa | Q7: Académicos de otros programas o unidades de la institución | T7: Académicos externos a la institución asociados al proyecto | W7: Jefes de práctica (N°) | X7: Investigadores posdoctorales (N°) | Y7: Estudiantes y tesistas de pregrado (número total) | AJ7: Estudiantes y tesistas de posgrado (número total) | AN7: Impacto y productos comprometidos | AP7: Mecanismos de difusión y tranferencia del proyecto y sus resusltados de cara a actores clave | AT7: Financiamiento y apoyos
A8: # | B8: Año inicio | C8: Año de término | D8: Duración total (meses) | E8: Nombre del proyecto | F8: Tipo de proyecto | G8: Resumen general | H8: Linea(s) de investigación del programa en la que se integra | I8: Investigador(a) responsable | J8: Nombre(s) | K8: Institución a la que pertenece | L8: Programa | M8: Nombres | N8: N° total | O8: Nombres | P8: N° total | Q8: Nombres | R8: Programa o unidad | S8: N° total | T8: Nombres | U8: Institución | V8: N° total | Y8: 1er año | Z8: 2do año | AA8: 3er año | AB8: 4to año | AC8: 5to año | AD8: > 5to años | AE8: Total | AF8: Estudiantes de otros programas de la institución | AG8: Tesistas del programa | AH8: Tesistas de otros programas pregrado de la institución | AI8: Graduados o titulados del programa | AJ8: Estudiantes de postgrado de la institución | AK8: Estudiantes de postgrado de otras instituciones | AL8: Tesistas de posgrado de la institución | AM8: Tesistas de posgrado de otras instituciones | AN8: Impacto del proyecto para el desarrollo del programa | AO8: Actividades o productos desarrollados o comprometidos en el marco del proyecto | AP8: El programa y la institución | AQ8: El público general y el entorno significativo del programa | AR8: La comunidad académica y disciplinar nacional e internacional | AS8: La industria | AT8: Interno (en USD) | AU8: Externo (en USD) | AV8: Origen del financiamiento externo | AW8: Costo total del proyecto (En USD) | AX8: Apoyos y patrocinios de instituciones nacionales (en USD) | AY8: Apoyos y patrocinios de instituciones Internacionales (en USD)
A9: 1 | AW9: =AQ9+AR9 -> 0
A10: 2 | AW10: =AQ10+AR10 -> 0
A11: 3 | AW11: =AQ11+AR11 -> 0
A12: 4 | AW12: =AQ12+AR12 -> 0
A13: 5 | AW13: =AQ13+AR13 -> 0
A14: 6 | AW14: =AQ14+AR14 -> 0
A15: 7 | AW15: =AQ15+AR15 -> 0
A16: 8 | AW16: =AQ16+AR16 -> 0
A17: 9 | AW17: =AQ17+AR17 -> 0
A18: 10 | AW18: =AQ18+AR18 -> 0
A19: 11 | AW19: =AQ19+AR19 -> 0
A20: 12 | AW20: =AQ20+AR20 -> 0
... A58: 50 | AW58: =AQ58+AR58 -> 0

Sheet 21. Desarrollo profesional
A1: ACTIVIDADES DE DESARROLLO PROFESIONAL CONDUCIDAS POR ACADÉMICOS DEL PROGRAMA (ÚLTIMOS 5 AÑOS)
A3: Esta sección recopila información acerca de las actividades de desarrollo profesional conducidas por docentes e investigadores del programa, en los últimos 5 años.
A4: En el contexto de esta Guía se entenderá como actividades de desarrollo profesional a aquellos proyectos o actividades que involucren mecanismos de transferencia tecnológica y de conocimientos entre el mundo académico y entornos privados o públicos asociados a la industria, los servicios o el desarrollo de políticas públicas como asesorías de carácter profesional; actividades profesionales o académicas externas realizadas por invitación de instituciones de carácter profesional; proyectos de asistencia técnica (por ejemplo, informes de impacto ambiental o informes tecnicos para organizamos del Estado); cursos para empresas o para reparticiones públicas; consultorías; asesorías; o estudios para el impulso de normas y reglamentos legales en su área de experiencia, planes de desarrollo urbano y territorial, entre otras.
B6: Identificación general | J6: Objetivos y productos
A7: # | B7: Año | C7: Fecha de inicio | D7: Fecha de termino | E7: Responsable(s) | F7: Tipo de proyecto o actividad proyecto o actividad | G7: Resumen | H7: Linea de investigación del programa con la que se vincula | I7: Contraparte | J7: Objetivos | K7: Producto(s) | L7: Link | M7: Observaciones
A8: 1
A9: 2
A10: 3
A11: 4
A12: 5
A13: 6
A14: 7
A15: 8
A16: 9
A17: 10
A18: 11
A19: 12
... A57: 50

Sheet 22. Artículos
A1: ARTÍCULOS CIENTÍFICOS DESARROLLADOS POR LOS ACADÉMICOS DEL PROGRAMA (ÚLTIMOS 5 AÑOS)
A3: En esta sección se recolecta información acerca de los artículos científicos desarrollados por los docentes e investigadores del programa en los últimos 5 años. En caso de que una publicación tenga más de un autor o autora incluir sus nombres separados por punto y coma (;).
B4: Identificación general del artículo | H4: Características de la publicación | M4: Estado publicación (Seleccionar una de las siguientes: enviado, en revisión, aceptado, publicado) | N4: Identificadores y referencias
A5: # | B5: Año | C5: Título de la publicación | D5: Autor(es) del programa | E5: Autores externos al programa | F5: Línea de investigación del programa en la que se inserta | G5: Proyecto de investigación al que está ligado | H5: Tipo de publicación (artículo, review, conference paper o proceeding) | I5: Revista | J5: Tipo de revista (nacional, internacional) | K5: Indexación | L5: Institución responsable de la publicación | N5: ISSN | O5: DOI | P5: Link | Q5: Observaciones
A6: 1
A7: 2
A8: 3
A9: 4
A10: 5
A11: 6
A12: 7
A13: 8
A14: 9
A15: 10
A16: 11
A17: 12
... A55: 50

Sheet 23. Libros o Capítulos de libro
A1: LIBROS Y CAPITULOS DE LIBROS DESARROLLADOS POR LOS ACADÉMICOS DEL PROGRAMA (ÚLTIMOS 5 AÑOS)
A3: En esta sección se recolecta información acerca de los libros y capítulos de libro escritos por los docentes e investigadores del programa en los últimos 5 años. En caso de que una publicación tenga más de un autor o autora incluir sus nombres separados por punto y coma (;).
A5: # | B5: Año | C5: Tipo de publicación | D5: Título | E5: Autor(es) | F5: Línea de investigación del programa en la que se inserta | G5: Título del libro (Si es un capítulo) | H5: Autor(es) del libro (Si es un capítulo) | I5: ¿Tiene refereto externo? (sí/no) | J5: Editorial | K5: Estado publicación | L5: ISBN | M5: Link | N5: Observaciones
A6: 1
A7: 2
A8: 3
A9: 4
A10: 5
A11: 6
A12: 7
A13: 8
A14: 9
A15: 10
A16: 11
A17: 12
... A55: 50

Sheet 24. Obra de creación
A1: OBRAS DE CREACIÓN DESARROLLADAS POR LOS ACADÉMICOS DEL PROGRAMA (ÚLTIMOS 5 AÑOS)
A3: Esta sección recopila información acerca de las obras de creación desarrolladas por docentes e investigadores del programa, en los últimos 5 años.
A4: En el contexto de esta Guía se entenderá como obra de creación a aquellas que representen aportes originales al conocimiento y el avance de las artes, la arquitectura, el diseño, las humanidades, el rescate patrimonial y la cultura o el conocimiento en general, y que hayan sido realizadas en el marco de un proyecto o iniciativa reconocida.
A6: # | B6: Año | C6: Título de la obra | D6: Autor(es) | E6: Formato o soportes | F6: Registro de propiedad intelectual | G6: Linea de investigación del programa con la que se desarrolla | H6: Lugar(es) de exhibición | I6: Fecha de inauguración, lanzamiento o estreno (formato fecha corta) | J6: Curadores | K6: Referencias | L6: Link | M6: Observaciones
A7: 1
A8: 2
A9: 3
A10: 4
A11: 5
A12: 6
A13: 7
A14: 8
A15: 9
A16: 10
A17: 11
A18: 12
... A56: 50

Sheet 25. Patentes
A1: PATENTES DESARROLLADAS POR LOS ACADÉMICOS DEL PROGRAMA (ÚLTIMOS 5 AÑOS)
A3: Esta sección recopila información sobre el desarrollo de patentes llevado a cabo por los docentes e investigadores del programa.
A5: # | B5: Año | C5: Nombre de la patente | D5: Autor(es) | E5: Línea de investigación del programa en la que se inserta | F5: Fecha de solictud | G5: Fecha de publicación | H5: Código de la patente | I5: Estado | J5: Referencias | K5: Link | L5: Observaciones
A6: 1
A7: 2
A8: 3
A9: 4
A10: 5
A11: 6
A12: 7
A13: 8
A14: 9
A15: 10
A16: 11
A17: 12
... A55: 50

Sheet 26. Redes
A1: REDES DE COLABORACIÓN NACIONALES E INTERNACIONALES EN LAS QUE SE INSERTA EL PROGRAMA O SU UNIDAD RESPONSABLE
A3: Esta sección recoge información acerca de las redes de colaboración nacionales e internacionales de las que participa el programa o su unidad responsable, atendiendo a su carácter, objetivos, resultados o impacto, y a los mecanismos de vinculación desarrollados por el programa en torno a ellas
A5: Identificación de la Red | G5: Participación de actores del programa | K5: Resutados e impacto
A6: # | B6: Nombre de la Red | C6: Carácter (nacional, internacional) | D6: Institución responsable | E6: Instituciones asociadas | F6: Objetivos de la Red | G6: Encargado(a) vinculación con la Red en el programa | H6: N° académicos Tiempo Completo participantes | I6: N° académicos Tiempo Parcial participantes | J6: N° de estudiantes del programa participantes | K6: Actividades desarrolladas o comprometidas en el marco de la participación del programa en la Red | L6: Productos desarrollados o comprometidos en el marco de la participación del programa en la Red | M6: Mecanismos de difusión de actividades y productos de esta Red entre actores clave del programa | N6: Observaciones
A7: 1
A8: 2
A9: 3
A10: 4
A11: 5
A12: 6
A13: 7
A14: 8
A15: 9
A16: 10
A17: 11
A18: 12
... A56: 50

Sheet 27. Extensión
A1: ACTIVIDADES DE EXTENSIÓN MÁS RELEVANTES DESARROLLADAS POR EL PROGRAMA EN LOS ÚLTIMOS 5 AÑOS
A3: En esta sección se recolecta información acerca de las actividades de extensión desarrolladas por el programa en los últimos 5 años.
A4: En el marco propuesto por esta parta de la Guía de antecedentes, entenderemos por extensión aquellas actividades ligadas a la vinculación con el medio que impulsan intercambios de saberes científicos, tecnológicos y culturales entre el programa y su entorno significativo.
B6: Descripción general | G6: Duración actividad Formato fecha corta | I6: Partcipantes | L6: Resultados | O6: Financiamiento interno (Expresar monto en USD)
A7: # | B7: Nombre | C7: Descripción | D7: Relación con los objetivos o líneas de investigación del programa | E7: Responsable(s) | F7: Año de desarrollo | G7: Inicio | H7: Fin | I7: N° académicos del programa o su unidad responsable involucrados | J7: N° estudiantes del programa o su unidad responsable involucrados | K7: Publico o comunidades al que está dirigida la actividad | L7: Impacto para el desarrollo del programa | M7: Impacto para el publico objetivo de la actividad | N7: Mecanismos de evaluación | O7: Financiamiento interno (del programa o la institución) | P7: Financiamiento externo (ajeno a la institución) | Q7: Costo total de la actividad | R7: Observaciones
A8: 1 | Q8: =O8+P8 -> 0
A9: 2 | Q9: =O9+P9 -> 0
A10: 3 | Q10: =O10+P10 -> 0
A11: 4 | Q11: =O11+P11 -> 0
A12: 5 | Q12: =O12+P12 -> 0
A13: 6 | Q13: =O13+P13 -> 0
A14: 7 | Q14: =O14+P14 -> 0
A15: 8 | Q15: =O15+P15 -> 0
A16: 9 | Q16: =O16+P16 -> 0
A17: 10 | Q17: =O17+P17 -> 0
A18: 11 | Q18: =O18+P18 -> 0
A19: 12 | Q19: =O19+P19 -> 0
... A57: 50 | Q57: =O57+P57 -> 0

Sheet 28. Prestación de servicios
A1: ACTIVIDADES DE PRESTACIÓN DE SERVICIOS DESARROLLADAS POR EL PROGRAMA O SU UNIDAD RESPONSABLE (ÚLTIMOS 5 AÑOS)
A3: En esta sección se recopila información sobre las actividades de prestación de servicio llevadas adelante por el programa o su unidad responsable en los últimos 5 años, atendiendo a sus características generales, sus participantes, su impacto en el programa y en sus usuarios o contrapartes, entre otros elementos.
A4: Entenderemos por prestación de servicios a aquellas acciones desarrolladas por un programa o su unidad responsable con el fin de vincularse con su entorno significativo, generando -en dicho intercambio- recursos económicos o ganancias monetarias que pueden reinvertirse en el programa (formación continua; centros de idiomas; asistencia jurídica para personas naturales; analisis avanzados en laboratorios; atención clínica en hospitales especializados; servicios medico-forense; diseño de paisaje o planos.
B6: Identificación general | J6: Mecanismos de evaluación | M6: Mecanismos de difusión | N6: Presupuesto e ingresos generados
A7: # | B7: Año de inicio | C7: Actividad | D7: Responsable(s) | E7: Breve descripción de la actividad | F7: Público objetivo, usuarios o contrapartes | G7: N° académicos del programa o su unidad involucrados | H7: N° estudiantes del programa involucrados | I7: Beneficiarios o contrapartes | J7: Impacto en el logro de los objetivos del programa o en su perfil de egreso | K7: Impacto en el público objetivo, usuarios o contrapartes | L7: Mecanismos de evaluación | N7: Monto Financiamiento interno (en USD) | O7: Monto Financiamiento externo (en USD) | P7: Monto total del proyecto (en USD) | Q7: Recursos generados para el programa o su unidad responsable (en USD) | R7: Observaciones
A8: 1 | P8: =N8+O8 -> 0
A9: 2 | P9: =N9+O9 -> 0
A10: 3 | P10: =N10+O10 -> 0
A11: 4 | P11: =N11+O11 -> 0
A12: 5 | P12: =N12+O12 -> 0
A13: 6 | P13: =N13+O13 -> 0
A14: 7 | P14: =N14+O14 -> 0
A15: 8 | P15: =N15+O15 -> 0
A16: 9 | P16: =N16+O16 -> 0
A17: 10 | P17: =N17+O17 -> 0
A18: 11 | P18: =N18+O18 -> 0
A19: 12 | P19: =N19+O19 -> 0
... A57: 50 | P57: =N57+O57 -> 0

Sheet ÁREAS OCDE
A1: SUB-ÁREA OCDE | B1: ÁREA OCDE
A2: 1.1. MATEMÁTICAS | B2: CIENCIAS_NATURALES
A3: 1.2. COMPUTACIÓN Y CIENCIAS DE LA INFORMACIÓN | B3: INGENIERÍA_Y_TECNOLOGÍA
A4: 1.3. CIENCIAS FÍSICAS | B4: CIENCIAS_MÉDICAS_Y_DE_LA_SALUD
A5: 1.4. CIENCIAS QUÍMICAS | B5: CIENCIAS_AGRÍCOLAS
A6: 1.5. CIENCIAS DE LA TIERRA Y MEDIOAMBIENTALES | B6: CIENCIAS_SOCIALES
A7: 1.6. CIENCIAS BIOLÓGICAS | B7: HUMANIDADES
A8: 1.7. OTRAS CIENCIAS NATURALES
A9: 2.1. INGENIERÍA CIVIL
A10: 2.2. INGENIERÍA ELÉCTRICA, ELECTRÓNICA E INFORMÁTICA
A11: 2.3. INGENIERÍA MECÁNICA
A12: 2.4. INGENIERÍA QUÍMICA
A13: 2.5. INGENIERÍA DE LOS MATERIALES
A14: 2.6. INGENIERÍA MÉDICA
A15: 2.7. INGENIERÍA AMBIENTAL
A16: 2.8. BIOTECNOLOGÍA AMBIENTAL
A17: 2.9. BIOTECNOLOGÍA INDUSTRIAL
A18: 2.10. NANOTECNOLOGÍA
A19: 2.11. OTRAS INGENIERÍAS Y TECNOLOGÍAS
... A43: 6.5. OTRAS HUMANIDADES
